Workbook
Name AMAZONAS: #REF!
Name AMAZONAS: #REF!
Name AMAZONAS: #REF!
Name AMAZONAS: #REF!
Name AMAZONAS: #REF!
Name AMAZONAS: #REF!
Name AMAZONAS: #REF!
Name AMAZONAS: #REF!
Name AMAZONAS: #REF!
Name AMAZONAS: #REF!
Name AMAZONAS: #REF!
Name AMAZONAS: #REF!
Name AMAZONAS: #REF!
Name AMAZONAS: #REF!
Name AMAZONAS: #REF!
Name AMAZONAS: #REF!
Name AMAZONAS: #REF!
Name AMAZONAS: #REF!
Name AMAZONAS: #REF!
Name AMAZONAS: #REF!
Name AMAZONAS: #REF!
Name AMAZONAS: #REF!
Name AMAZONAS: #REF!
Name AMAZONAS: #REF!
Name AMAZONAS: #REF!
Name AMAZONAS: #REF!
Name AMAZONAS: #REF!
Name AMAZONAS: #REF!
Name ANCASH: #REF!
Name ANCASH: #REF!
Name ANCASH: #REF!
Name ANCASH: #REF!
Name ANCASH: #REF!
Name ANCASH: #REF!
Name ANCASH: #REF!
Name ANCASH: #REF!
Name ANCASH: #REF!
Name ANCASH: #REF!
Name ANCASH: #REF!
Name ANCASH: #REF!
Name ANCASH: #REF!
Name ANCASH: #REF!
Name ANCASH: #REF!
Name ANCASH: #REF!
Name ANCASH: #REF!
Name ANCASH: #REF!
Name ANCASH: #REF!
Name ANCASH: #REF!
Name ANCASH: #REF!
Name ANCASH: #REF!
Name ANCASH: #REF!
Name ANCASH: #REF!
Name ANCASH: #REF!
Name ANCASH: #REF!
Name ANCASH: #REF!
Name ANCASH: #REF!
Name APURIMAC: #REF!
Name APURIMAC: #REF!
Name APURIMAC: #REF!
Name APURIMAC: #REF!

Sheet 3.1
A1: 3. GENERACIÓN DE ENERGÍA ELÉCTRICA
A3: 3.1. EMPRESAS QUE GENERAN ENERGÍA ELÉCTRICA
B5: 3.1.1. Empresas generadoras de energía eléctrica para el mercado eléctrico * | G5: Informa A | H5: Informante
G6: Tipo de Mercado A | H6: Mercado Eléctrico
B7: Las empresas generadoras de energía eléctrica para el mercado eléctrico, son aquellas empresas que comercializan la energía eléctrica. En el año 2024, se registraron 92 empresas pertenecientes a esta categoría. | G7: FILTRO | H7: (en blanco)
B9: Nº | C9: Nombre de la empresa | D9: Abreviatura | G9: Empresa Anuario | H9: ABREVIATURA
B10: 1 | C10: =+G10 -> Agro Industrial Paramonga S.A.A. | D10: =+H10 -> AIPSA | G10: Agro Industrial Paramonga S.A.A. | H10: AIPSA
B11: =+B10+1 -> 2 | C11: =+G11 -> Agroaurora S.A.C. | D11: =+H11 -> AGROAURORA | G11: Agroaurora S.A.C. | H11: AGROAURORA
B12: =+B11+1 -> 3 | C12: =+G12 -> Agroindustrias San Jacinto S.A.A. | D12: =+H12 -> SAN JACINTO | G12: Agroindustrias San Jacinto S.A.A. | H12: SAN JACINTO
B13: =+B12+1 -> 4 | C13: =+G13 -> Amazonas Energía Solar S.A.C. | D13: =+H13 -> AMAZONAS ENERGÍA | G13: Amazonas Energía Solar S.A.C. | H13: AMAZONAS ENERGÍA
B14: =+B13+1 -> 5 | C14: =+G14 -> Andean Power S.A.C. | D14: =+H14 -> ANDEAN POWER | G14: Andean Power S.A.C. | H14: ANDEAN POWER
B15: =+B14+1 -> 6 | C15: =+G15 -> Asociación Santa Lucia de Chacas | D15: =+H15 -> CHACAS | G15: Asociación Santa Lucia de Chacas | H15: CHACAS
B16: =+B15+1 -> 7 | C16: =+G16 -> Atria Energía S.A.C. | D16: =+H16 -> ATRIA ENERGIA | G16: Atria Energía S.A.C. | H16: ATRIA ENERGIA
B17: =+B16+1 -> 8 | C17: =+G17 -> Bioenergía del Chira S.A. | D17: =+H17 -> BIOCHIRA | G17: Bioenergía del Chira S.A. | H17: BIOCHIRA
B18: =+B17+1 -> 9 | C18: =+G18 -> Celepsa Renovables S.R.L. | D18: =+H18 -> CELEPSA RENOVABLES | G18: Celepsa Renovables S.R.L. | H18: CELEPSA RENOVABLES
B19: =+B18+1 -> 10 | C19: =+G19 -> Central Hidroeléctrica de Langui S.A. | D19: =+H19 -> LANGUI | G19: Central Hidroeléctrica de Langui S.A. | H19: LANGUI
B20: =+B19+1 -> 11 | C20: =+G20 -> Centrales Santa Rosa S.A.C. | D20: =+H20 -> CENT. SANTA ROSA | G20: Centrales Santa Rosa S.A.C. | H20: CENT. SANTA ROSA
B21: =+B20+1 -> 12 | C21: =+G21 -> Chinango S.A.C | D21: =+H21 -> CHINANGO | G21: Chinango S.A.C | H21: CHINANGO
B22: =+B21+1 -> 13 | C22: =+G22 -> Cía Hidroeléctrica San Hilarión S.A.C. | D22: =+H22 -> SAN HILARIÓN | G22: Cía Hidroeléctrica San Hilarión S.A.C. | H22: SAN HILARIÓN
... B101: =+B100+1 -> 92 | C101: =+G101 -> Termoselva S.R.L. | D101: =+H101 -> TERMOSELVA | G101: Termoselva S.R.L. | H101: TERMOSELVA
B102: (*) Sólo empresas que informan a la DGE del MINEM. Asimismo incluye información de empresas distribuidoras que cuentan con centrales de generación eléctrica. | G102: Total general
B103: (1) A partir de agosto de 2024, Enel Distribución Perú cambió de razon social a Pluz Energía Perú S.A.A.
B104: (2) A partir del mes agosto 2024, la empresa Enel Generación Perú cambia de razón social a Orygen Perú S.A.A.
B105: (3) A partir del mes de julio 2024, la C.T. Oquendo de la empresa Cogeneración Oquendo S.A.C. pasa a ser administrado por la empresa SDF Energía S.A.C.

Sheet 3.1.2
A1: 3.1.2. Empresas generadoras de energía eléctrica para uso propio * | F1: Informa A | G1: Informante
F2: Tipo de Mercado A | G2: Uso Propio
B3: Las empresas generadoras de energía eléctrica para uso propio, son aquellas empresas cuya actividad principal no es la generación de energía eléctrica; sin embargo, cuentan con centrales eléctricas. En el año 2024, se registraron 93 empresas pertenecientes a esta categoría. | F3: FILTRO | G3: (en blanco)
B5: Nº | C5: Nombre de la empresa | D5: Abreviatura | F5: Empresa Anuario | G5: ABREVIATURA
B6: 1 | C6: Agroindustrial Laredo S.A.A. | D6: =+G6 -> LAREDO | F6: Agroindustrial Laredo S.A.A. | G6: LAREDO
B7: =+B6+1 -> 2 | C7: Agrolmos S.A. (1) | D7: =+G7 -> AGROLMOS | F7: Agrolmos S.A. | G7: AGROLMOS
B8: =+B7+1 -> 3 | C8: Aguaytia Energy del Peru S.R.L. | D8: =+G8 -> AGUAYTÍA | F8: Aguaytia Energy del Peru S.R.L. | G8: AGUAYTÍA
B9: =+B8+1 -> 4 | C9: Ajeper S.A. | D9: =+G9 -> AJEPER | F9: Ajeper S.A. | G9: AJEPER
B10: =+B9+1 -> 5 | C10: Ajinomoto del Peru S.A. | D10: =+G10 -> AJINOM | F10: Ajinomoto del Peru S.A. | G10: AJINOM
B11: =+B10+1 -> 6 | C11: Alicorp S.A.A. | D11: =+G11 -> ALICORP | F11: Alicorp S.A.A. | G11: ALICORP
B12: =+B11+1 -> 7 | C12: Anabi S.A.C. | D12: =+G12 -> ANABI | F12: Anabi S.A.C. | G12: ANABI
B13: =+B12+1 -> 8 | C13: Anglo American Quellaveco S.A. | D13: =+G13 -> QUELLAVECO | F13: Anglo American Quellaveco S.A. | G13: QUELLAVECO
B14: =+B13+1 -> 9 | C14: APM Terminals Callao S.A. | D14: =+G14 -> APMTER | F14: APM Terminals Callao S.A. | G14: APMTER
B15: =+B14+1 -> 10 | C15: Apumayo S.A.C. | D15: =+G15 -> APUMAYO | F15: Apumayo S.A.C. | G15: APUMAYO
B16: =+B15+1 -> 11 | C16: Aris Indsutrial S.A. (1) | D16: =+G16 -> ARIS | F16: Aris Indsutrial S.A. | G16: ARIS
B17: =+B16+1 -> 12 | C17: Aruntani S.A.C. | D17: =+G17 -> ARUNTANI | F17: Aruntani S.A.C. | G17: ARUNTANI
B18: =+B17+1 -> 13 | C18: Austral Group S.A.A | D18: =+G18 -> AUSTRAL | F18: Austral Group S.A.A | G18: AUSTRAL
... B98: =+B97+1 -> 93 | C98: Yura S.A. | D98: =+G98 -> YURASA | F98: Yura S.A. | G98: YURASA
B99: (*) Sólo empresas que informan a la DGE del MINEM. | F99: Total general
B100: (1) Las empresas Agrolmos S.A., Aris Indsutrial S.A., Flesan Indutrial Power S.A.C y Progenere S.A.C. comenzaron a informar a la DGE del MINEM a partir del mes de enero 2024
B101: (2) La empresa OIG Perú S.A.C. empezó a informar a partir del mes de mayo 2024.

Sheet 3.2.1.1
A1: 3.2.1. Número de centrales y grupos eléctricos por empresas | AI1: Informa A | AJ1: Informante
AI2: Tipo de Mercado A | AJ2: Mercado Eléctrico | AN2: Informa A | AO2: Informante
B3: 3.2.1.1. Para el mercado eléctrico (*) | AI3: Nom Gru Anuario | AJ3: (Todas) | AN3: Tipo de Mercado A | AO3: Mercado Eléctrico
AI4: Variable | AJ4: Energía | AN4: Variable | AO4: Energía
D5: Número | E5: Número | F5: Hidráulicas | H5: Térmicas | M5: Solares | N5: Eólicas | X5: Cuenta de Nom Gru Anuario | Y5: Etiquetas de columna | AI5: FILTRO | AJ5: (en blanco) | AN5: FILTRO | AO5: (en blanco)
B6: Nº | C6: Principales empresas | D6: de | E6: de | F6: Nº | G6: Nº | H6: Nº | I6: Nº de Grupos | M6: Nº | N6: Nº | Q6: Cuenta de Central Anuario | R6: Etiquetas de columna | Y6: Hidráulico | Z6: Térmico | AD6: Solar | AE6: Eólico
D7: Centrales | E7: Grupos | F7: Centrales | G7: Grupos | H7: Centrales | I7: EL | J7: TG | K7: TV | L7: CC | M7: Centrales | N7: Centrales | Q7: Etiquetas de fila | R7: Hidráulico | S7: Térmico | T7: Solar | U7: Eólico | V7: Total general | X7: Etiquetas de fila | Y7: HI | Z7: CC | AA7: EL | AB7: TG | AC7: TV | AD7: HI | AE7: HI | AI7: Empresa Anuario | AJ7: Origen A | AK7: Central Anuario | AN7: Empresa Anuario | AO7: Central Anuario | AP7: Nom Gru Anuario | AQ7: Origen A | AR7: CTIPGRU
B8: 1 | C8: =+Q8 -> Agro Industrial Paramonga S.A.A. | D8: =+SUM(F8,H8,M8:N8) -> 1 | E8: =+SUM(G8,I8:L8) -> 1 | F8: =+IF(R8<>"",R8,"") | G8: =+IF(Y8<>"",Y8,"") | H8: =+IF(S8<>"",S8,"") -> 1 | I8: =+IF(AA8<>"",AA8,"") | J8: =+IF(AB8<>"",AB8,"") | K8: =+IF(AC8<>"",AC8,"") -> 1 | L8: =+IF(Z8<>"",Z8,"") | M8: =+IF(T8<>"",T8,"") | N8: =+IF(U8<>"",U8,"") | Q8: Agro Industrial Paramonga S.A.A. | S8: 1 | V8: 1 | X8: Agro Industrial Paramonga S.A.A. | AC8: 1 | AI8: Agro Industrial Paramonga S.A.A. | AJ8: Térmico | AK8: C.T. PARAMONGA | AN8: Agro Industrial Paramonga S.A.A. | AO8: C.T. PARAMONGA | AP8: TV01 | AQ8: Térmico | AR8: TV
B9: =+B8+1 -> 2 | C9: =+Q9 -> Agroaurora S.A.C. | D9: =+SUM(F9,H9,M9:N9) -> 1 | E9: =+SUM(G9,I9:L9) -> 1 | F9: =+IF(R9<>"",R9,"") | G9: =+IF(Y9<>"",Y9,"") | H9: =+IF(S9<>"",S9,"") -> 1 | I9: =+IF(AA9<>"",AA9,"") | J9: =+IF(AB9<>"",AB9,"") | K9: =+IF(AC9<>"",AC9,"") -> 1 | L9: =+IF(Z9<>"",Z9,"") | M9: =+IF(T9<>"",T9,"") | N9: =+IF(U9<>"",U9,"") | Q9: Agroaurora S.A.C. | S9: 1 | V9: 1 | X9: Agroaurora S.A.C. | AC9: 1 | AI9: Agroaurora S.A.C. | AJ9: Térmico | AK9: C.T. AGROAURORA | AN9: Agroaurora S.A.C. | AO9: C.T. AGROAURORA | AP9: G1 | AQ9: Térmico | AR9: TV
B10: =+B9+1 -> 3 | C10: =+Q10 -> Agroindustrias San Jacinto S.A.A. | D10: =+SUM(F10,H10,M10:N10) -> 1 | E10: =+SUM(G10,I10:L10) -> 1 | F10: =+IF(R10<>"",R10,"") | G10: =+IF(Y10<>"",Y10,"") | H10: =+IF(S10<>"",S10,"") -> 1 | I10: =+IF(AA10<>"",AA10,"") | J10: =+IF(AB10<>"",AB10,"") | K10: =+IF(AC10<>"",AC10,"") -> 1 | L10: =+IF(Z10<>"",Z10,"") | M10: =+IF(T10<>"",T10,"") | N10: =+IF(U10<>"",U10,"") | Q10: Agroindustrias San Jacinto S.A.A. | S10: 1 | V10: 1 | X10: Agroindustrias San Jacinto S.A.A. | AC10: 1 | AI10: Agroindustrias San Jacinto S.A.A. | AJ10: Térmico | AK10: C.T. SAN JACINTO | AN10: Agroindustrias San Jacinto S.A.A. | AO10: C.T. SAN JACINTO | AP10: TV1 | AQ10: Térmico | AR10: TV
B11: =+B10+1 -> 4 | C11: =+Q11 -> Amazonas Energía Solar S.A.C. | D11: =+SUM(F11,H11,M11:N11) -> 3 | E11: - | F11: =+IF(R11<>"",R11,"") | G11: =+IF(Y11<>"",Y11,"") | H11: =+IF(S11<>"",S11,"") | I11: =+IF(AA11<>"",AA11,"") | J11: =+IF(AB11<>"",AB11,"") | K11: =+IF(AC11<>"",AC11,"") | L11: =+IF(Z11<>"",Z11,"") | M11: =+IF(T11<>"",T11,"") -> 3 | N11: =+IF(U11<>"",U11,"") | Q11: Amazonas Energía Solar S.A.C. | T11: 3 | V11: 3 | X11: Amazonas Energía Solar S.A.C. | AD11: 3 | AI11: Amazonas Energía Solar S.A.C. | AJ11: Solar | AK11: C.S.F. SAN LORENZO | AN11: Amazonas Energía Solar S.A.C. | AO11: C.S.F. SAN LORENZO | AP11: Total Central | AQ11: Solar | AR11: HI
B12: =+B11+1 -> 5 | C12: =+Q12 -> Andean Power S.A.C. | D12: =+SUM(F12,H12,M12:N12) -> 1 | E12: =+SUM(G12,I12:L12) -> 2 | F12: =+IF(R12<>"",R12,"") -> 1 | G12: =+IF(Y12<>"",Y12,"") -> 2 | H12: =+IF(S12<>"",S12,"") | I12: =+IF(AA12<>"",AA12,"") | J12: =+IF(AB12<>"",AB12,"") | K12: =+IF(AC12<>"",AC12,"") | L12: =+IF(Z12<>"",Z12,"") | M12: =+IF(T12<>"",T12,"") | N12: =+IF(U12<>"",U12,"") | Q12: Andean Power S.A.C. | R12: 1 | V12: 1 | X12: Andean Power S.A.C. | Y12: 2 | AI12: Amazonas Energía Solar S.A.C. | AJ12: Solar | AK12: C.S.F. REQUENA | AN12: Amazonas Energía Solar S.A.C. | AO12: C.S.F. REQUENA | AP12: Total Central | AQ12: Solar | AR12: HI
B13: =+B12+1 -> 6 | C13: =+Q13 -> Asociación Santa Lucia de Chacas | D13: =+SUM(F13,H13,M13:N13) -> 1 | E13: =+SUM(G13,I13:L13) -> 1 | F13: =+IF(R13<>"",R13,"") -> 1 | G13: =+IF(Y13<>"",Y13,"") -> 1 | H13: =+IF(S13<>"",S13,"") | I13: =+IF(AA13<>"",AA13,"") | J13: =+IF(AB13<>"",AB13,"") | K13: =+IF(AC13<>"",AC13,"") | L13: =+IF(Z13<>"",Z13,"") | M13: =+IF(T13<>"",T13,"") | N13: =+IF(U13<>"",U13,"") | Q13: Asociación Santa Lucia de Chacas | R13: 1 | V13: 1 | X13: Asociación Santa Lucia de Chacas | Y13: 1 | AI13: Amazonas Energía Solar S.A.C. | AJ13: Solar | AK13: C.S.F TAMSHIYACU | AN13: Amazonas Energía Solar S.A.C. | AO13: C.S.F TAMSHIYACU | AP13: Total Central | AQ13: Solar | AR13: HI
B14: =+B13+1 -> 7 | C14: =+Q14 -> Atria Energía S.A.C. | D14: =+SUM(F14,H14,M14:N14) -> 1 | E14: =+SUM(G14,I14:L14) -> 1 | F14: =+IF(R14<>"",R14,"") -> 1 | G14: =+IF(Y14<>"",Y14,"") -> 1 | H14: =+IF(S14<>"",S14,"") | I14: =+IF(AA14<>"",AA14,"") | J14: =+IF(AB14<>"",AB14,"") | K14: =+IF(AC14<>"",AC14,"") | L14: =+IF(Z14<>"",Z14,"") | M14: =+IF(T14<>"",T14,"") | N14: =+IF(U14<>"",U14,"") | Q14: Atria Energía S.A.C. | R14: 1 | V14: 1 | X14: Atria Energía S.A.C. | Y14: 1 | AI14: Andean Power S.A.C. | AJ14: Hidráulico | AK14: C.H. CARHUAC | AN14: Andean Power S.A.C. | AO14: C.H. CARHUAC | AP14: G-01 | AQ14: Hidráulico | AR14: HI
B15: =+B14+1 -> 8 | C15: =+Q15 -> Bioenergía del Chira S.A. | D15: =+SUM(F15,H15,M15:N15) -> 1 | E15: =+SUM(G15,I15:L15) -> 2 | F15: =+IF(R15<>"",R15,"") | G15: =+IF(Y15<>"",Y15,"") | H15: =+IF(S15<>"",S15,"") -> 1 | I15: =+IF(AA15<>"",AA15,"") | J15: =+IF(AB15<>"",AB15,"") | K15: =+IF(AC15<>"",AC15,"") -> 2 | L15: =+IF(Z15<>"",Z15,"") | M15: =+IF(T15<>"",T15,"") | N15: =+IF(U15<>"",U15,"") | Q15: Bioenergía del Chira S.A. | S15: 1 | V15: 1 | X15: Bioenergía del Chira S.A. | AC15: 2 | AI15: Asociación Santa Lucia de Chacas | AJ15: Hidráulico | AK15: C.H. HUALLÍN I | AN15: Andean Power S.A.C. | AO15: C.H. CARHUAC | AP15: G-02 | AQ15: Hidráulico | AR15: HI
B16: =+B15+1 -> 9 | C16: =+Q16 -> Celepsa Renovables S.R.L. | D16: =+SUM(F16,H16,M16:N16) -> 1 | E16: =+SUM(G16,I16:L16) -> 3 | F16: =+IF(R16<>"",R16,"") -> 1 | G16: =+IF(Y16<>"",Y16,"") -> 3 | H16: =+IF(S16<>"",S16,"") | I16: =+IF(AA16<>"",AA16,"") | J16: =+IF(AB16<>"",AB16,"") | K16: =+IF(AC16<>"",AC16,"") | L16: =+IF(Z16<>"",Z16,"") | M16: =+IF(T16<>"",T16,"") | N16: =+IF(U16<>"",U16,"") | Q16: Celepsa Renovables S.R.L. | R16: 1 | V16: 1 | X16: Celepsa Renovables S.R.L. | Y16: 3 | AI16: Atria Energía S.A.C. | AJ16: Hidráulico | AK16: C.H. PURMACANA | AN16: Asociación Santa Lucia de Chacas | AO16: C.H. HUALLÍN I | AP16: G1 | AQ16: Hidráulico | AR16: HI
B17: =+B16+1 -> 10 | C17: =+Q17 -> Central Hidroeléctrica de Langui S.A. | D17: =+SUM(F17,H17,M17:N17) -> 1 | E17: =+SUM(G17,I17:L17) -> 3 | F17: =+IF(R17<>"",R17,"") -> 1 | G17: =+IF(Y17<>"",Y17,"") -> 3 | H17: =+IF(S17<>"",S17,"") | I17: =+IF(AA17<>"",AA17,"") | J17: =+IF(AB17<>"",AB17,"") | K17: =+IF(AC17<>"",AC17,"") | L17: =+IF(Z17<>"",Z17,"") | M17: =+IF(T17<>"",T17,"") | N17: =+IF(U17<>"",U17,"") | Q17: Central Hidroeléctrica de Langui S.A. | R17: 1 | V17: 1 | X17: Central Hidroeléctrica de Langui S.A. | Y17: 3 | AI17: Bioenergía del Chira S.A. | AJ17: Térmico | AK17: C.T. CAÑA BRAVA | AN17: Atria Energía S.A.C. | AO17: C.H. PURMACANA | AP17: G1 | AQ17: Hidráulico | AR17: HI
B18: =+B17+1 -> 11 | C18: =+Q18 -> Centrales Santa Rosa S.A.C. | D18: =+SUM(F18,H18,M18:N18) -> 2 | E18: =+SUM(G18,I18:L18) -> 2 | F18: =+IF(R18<>"",R18,"") -> 2 | G18: =+IF(Y18<>"",Y18,"") -> 2 | H18: =+IF(S18<>"",S18,"") | I18: =+IF(AA18<>"",AA18,"") | J18: =+IF(AB18<>"",AB18,"") | K18: =+IF(AC18<>"",AC18,"") | L18: =+IF(Z18<>"",Z18,"") | M18: =+IF(T18<>"",T18,"") | N18: =+IF(U18<>"",U18,"") | Q18: Centrales Santa Rosa S.A.C. | R18: 2 | V18: 2 | X18: Centrales Santa Rosa S.A.C. | Y18: 2 | AI18: Celepsa Renovables S.R.L. | AJ18: Hidráulico | AK18: C.H. MARAÑON | AN18: Bioenergía del Chira S.A. | AO18: C.T. CAÑA BRAVA | AP18: TM5000 | AQ18: Térmico | AR18: TV
B19: =+B18+1 -> 12 | C19: =+Q19 -> Chinango S.A.C | D19: =+SUM(F19,H19,M19:N19) -> 2 | E19: =+SUM(G19,I19:L19) -> 3 | F19: =+IF(R19<>"",R19,"") -> 2 | G19: =+IF(Y19<>"",Y19,"") -> 3 | H19: =+IF(S19<>"",S19,"") | I19: =+IF(AA19<>"",AA19,"") | J19: =+IF(AB19<>"",AB19,"") | K19: =+IF(AC19<>"",AC19,"") | L19: =+IF(Z19<>"",Z19,"") | M19: =+IF(T19<>"",T19,"") | N19: =+IF(U19<>"",U19,"") | Q19: Chinango S.A.C | R19: 2 | V19: 2 | X19: Chinango S.A.C | Y19: 3 | AI19: Central Hidroeléctrica de Langui S.A. | AJ19: Hidráulico | AK19: C.H. LANGUI | AN19: Bioenergía del Chira S.A. | AO19: C.T. CAÑA BRAVA | AP19: TMC5000 | AQ19: Térmico | AR19: TV
B20: =+B19+1 -> 13 | C20: =+Q20 -> Cía Hidroeléctrica San Hilarión S.A.C. | D20: =+SUM(F20,H20,M20:N20) -> 1 | E20: =+SUM(G20,I20:L20) -> 1 | F20: =+IF(R20<>"",R20,"") -> 1 | G20: =+IF(Y20<>"",Y20,"") -> 1 | H20: =+IF(S20<>"",S20,"") | I20: =+IF(AA20<>"",AA20,"") | J20: =+IF(AB20<>"",AB20,"") | K20: =+IF(AC20<>"",AC20,"") | L20: =+IF(Z20<>"",Z20,"") | M20: =+IF(T20<>"",T20,"") | N20: =+IF(U20<>"",U20,"") | Q20: Cía Hidroeléctrica San Hilarión S.A.C. | R20: 1 | V20: 1 | X20: Cía Hidroeléctrica San Hilarión S.A.C. | Y20: 1 | AI20: Centrales Santa Rosa S.A.C. | AJ20: Hidráulico | AK20: C.H. SANTA ROSA I | AN20: Celepsa Renovables S.R.L. | AO20: C.H. MARAÑON | AP20: FRANCIS 1 | AQ20: Hidráulico | AR20: HI
B21: =+B20+1 -> 14 | C21: =+Q21 -> Cogeneración Oquendo S.A.C. | D21: - | E21: - | F21: =+IF(R21<>"",R21,"") | G21: =+IF(Y21<>"",Y21,"") | H21: - | I21: =+IF(AA21<>"",AA21,"") | J21: - | K21: - | L21: =+IF(Z21<>"",Z21,"") | M21: =+IF(T21<>"",T21,"") | N21: =+IF(U21<>"",U21,"") | Q21: Cogeneración Oquendo S.A.C. | S21: 1 | V21: 1 | X21: Cogeneración Oquendo S.A.C. | AB21: 1 | AC21: 2 | AI21: Centrales Santa Rosa S.A.C. | AJ21: Hidráulico | AK21: C.H. SANTA ROSA II | AN21: Celepsa Renovables S.R.L. | AO21: C.H. MARAÑON | AP21: FRANCIS 2 | AQ21: Hidráulico | AR21: HI
B22: =+B21+1 -> 15 | C22: =+Q22 -> Colca Solar S.A.C. | D22: =+SUM(F22,H22,M22:N22) -> 1 | E22: - | F22: =+IF(R22<>"",R22,"") | G22: =+IF(Y22<>"",Y22,"") | H22: =+IF(S22<>"",S22,"") | I22: =+IF(AA22<>"",AA22,"") | J22: =+IF(AB22<>"",AB22,"") | K22: =+IF(AC22<>"",AC22,"") | L22: =+IF(Z22<>"",Z22,"") | M22: =+IF(T22<>"",T22,"") -> 1 | N22: =+IF(U22<>"",U22,"") | Q22: Colca Solar S.A.C. | T22: 1 | V22: 1 | X22: Colca Solar S.A.C. | AD22: 1 | AI22: Chinango S.A.C | AJ22: Hidráulico | AK22: C.H. CHIMAY | AN22: Celepsa Renovables S.R.L. | AO22: C.H. MARAÑON | AP22: FRANCIS 3 | AQ22: Hidráulico | AR22: HI
B23: =+B22+1 -> 16 | C23: =+Q23 -> Compañia Eléctrica El Platanal S.A. | D23: =+SUM(F23,H23,M23:N23) -> 1 | E23: =+SUM(G23,I23:L23) -> 2 | F23: =+IF(R23<>"",R23,"") -> 1 | G23: =+IF(Y23<>"",Y23,"") -> 2 | H23: =+IF(S23<>"",S23,"") | I23: =+IF(AA23<>"",AA23,"") | J23: =+IF(AB23<>"",AB23,"") | K23: =+IF(AC23<>"",AC23,"") | L23: =+IF(Z23<>"",Z23,"") | M23: =+IF(T23<>"",T23,"") | N23: =+IF(U23<>"",U23,"") | Q23: Compañia Eléctrica El Platanal S.A. | R23: 1 | V23: 1 | X23: Compañia Eléctrica El Platanal S.A. | Y23: 2 | AI23: Chinango S.A.C | AJ23: Hidráulico | AK23: C.H. YANANGO | AN23: Central Hidroeléctrica de Langui S.A. | AO23: C.H. LANGUI | AP23: GRUPO 1 | AQ23: Hidráulico | AR23: HI
B24: =+B23+1 -> 17 | C24: =+Q24 -> Compañia Hidroeléctrica Tingo S.A. | D24: =+SUM(F24,H24,M24:N24) -> 1 | E24: =+SUM(G24,I24:L24) -> 4 | F24: =+IF(R24<>"",R24,"") -> 1 | G24: 4 | H24: =+IF(S24<>"",S24,"") | I24: =+IF(AA24<>"",AA24,"") | J24: =+IF(AB24<>"",AB24,"") | K24: =+IF(AC24<>"",AC24,"") | L24: =+IF(Z24<>"",Z24,"") | M24: =+IF(T24<>"",T24,"") | N24: =+IF(U24<>"",U24,"") | Q24: Compañia Hidroeléctrica Tingo S.A. | R24: 1 | V24: 1 | X24: Compañia Hidroeléctrica Tingo S.A. | Y24: 1 | AI24: Cía Hidroeléctrica San Hilarión S.A.C. | AJ24: Hidráulico | AK24: C.H. SAN HILARION | AN24: Central Hidroeléctrica de Langui S.A. | AO24: C.H. LANGUI | AP24: Grupo 2 | AQ24: Hidráulico | AR24: HI
B25: =+B24+1 -> 18 | C25: =+Q25 -> Consorcio Eléctrico Villacurí S.A.C. | D25: =+SUM(F25,H25,M25:N25) -> 3 | E25: =+SUM(G25,I25:L25) -> 3 | F25: =+IF(R25<>"",R25,"") -> 1 | G25: =+IF(Y25<>"",Y25,"") -> 1 | H25: =+IF(S25<>"",S25,"") -> 2 | I25: =+IF(AA25<>"",AA25,"") -> 2 | J25: =+IF(AB25<>"",AB25,"") | K25: =+IF(AC25<>"",AC25,"") | L25: =+IF(Z25<>"",Z25,"") | M25: =+IF(T25<>"",T25,"") | N25: =+IF(U25<>"",U25,"") | Q25: Consorcio Eléctrico Villacurí S.A.C. | R25: 1 | S25: 2 | V25: 3 | X25: Consorcio Eléctrico Villacurí S.A.C. | Y25: 1 | AA25: 2 | AI25: Cogeneración Oquendo S.A.C. | AJ25: Térmico | AK25: C.T. OQUENDO | AN25: Central Hidroeléctrica de Langui S.A. | AO25: C.H. LANGUI | AP25: Grupo 3 | AQ25: Hidráulico | AR25: HI
B26: =+B25+1 -> 19 | C26: =+Q26 -> E.A.W. Muller S.A. | D26: =+SUM(F26,H26,M26:N26) -> 1 | E26: =+SUM(G26,I26:L26) -> 3 | F26: =+IF(R26<>"",R26,"") -> 1 | G26: =+IF(Y26<>"",Y26,"") -> 3 | H26: =+IF(S26<>"",S26,"") | I26: =+IF(AA26<>"",AA26,"") | J26: =+IF(AB26<>"",AB26,"") | K26: =+IF(AC26<>"",AC26,"") | L26: =+IF(Z26<>"",Z26,"") | M26: =+IF(T26<>"",T26,"") | N26: =+IF(U26<>"",U26,"") | Q26: E.A.W. Muller S.A. | R26: 1 | V26: 1 | X26: E.A.W. Muller S.A. | Y26: 3 | AI26: Colca Solar S.A.C. | AJ26: Solar | AK26: C.S. YARUCAYA | AN26: Centrales Santa Rosa S.A.C. | AO26: C.H. SANTA ROSA I | AP26: G-1 | AQ26: Hidráulico | AR26: HI
B27: =+B26+1 -> 20 | C27: =+Q27 -> Eléctrica Yanapampa S.A.C. | D27: =+SUM(F27,H27,M27:N27) -> 1 | E27: =+SUM(G27,I27:L27) -> 3 | F27: =+IF(R27<>"",R27,"") -> 1 | G27: =+IF(Y27<>"",Y27,"") -> 3 | H27: =+IF(S27<>"",S27,"") | I27: =+IF(AA27<>"",AA27,"") | J27: =+IF(AB27<>"",AB27,"") | K27: =+IF(AC27<>"",AC27,"") | L27: =+IF(Z27<>"",Z27,"") | M27: =+IF(T27<>"",T27,"") | N27: =+IF(U27<>"",U27,"") | Q27: Eléctrica Yanapampa S.A.C. | R27: 1 | V27: 1 | X27: Eléctrica Yanapampa S.A.C. | Y27: 3 | AI27: Compañia Eléctrica El Platanal S.A. | AJ27: Hidráulico | AK27: C.H. EL PLATANAL | AN27: Centrales Santa Rosa S.A.C. | AO27: C.H. SANTA ROSA II | AP27: G-1 | AQ27: Hidráulico | AR27: HI
B28: =+B27+1 -> 21 | C28: =+Q28 -> Electro Dunas S.A.A. | D28: =+SUM(F28,H28,M28:N28) -> 4 | E28: =+SUM(G28,I28:L28) -> 9 | F28: =+IF(R28<>"",R28,"") -> 1 | G28: =+IF(Y28<>"",Y28,"") -> 2 | H28: =+IF(S28<>"",S28,"") -> 3 | I28: =+IF(AA28<>"",AA28,"") -> 7 | J28: =+IF(AB28<>"",AB28,"") | K28: =+IF(AC28<>"",AC28,"") | L28: =+IF(Z28<>"",Z28,"") | M28: =+IF(T28<>"",T28,"") | N28: =+IF(U28<>"",U28,"") | Q28: Electro Dunas S.A.A. | R28: 1 | S28: 3 | V28: 4 | X28: Electro Dunas S.A.A. | Y28: 2 | AA28: 7 | AI28: Compañia Hidroeléctrica Tingo S.A. | AJ28: Hidráulico | AK28: C.H. TINGO | AN28: Chinango S.A.C | AO28: C.H. CHIMAY | AP28: GR-1 | AQ28: Hidráulico | AR28: HI
B29: =+B28+1 -> 22 | C29: =+Q29 -> Electro Oriente S. A. | D29: =+SUM(F29,H29,M29:N29) -> 35 | E29: =+SUM(G29,I29:L29) -> 131 | F29: =+IF(R29<>"",R29,"") -> 10 | G29: =+IF(Y29<>"",Y29,"") -> 21 | H29: =+IF(S29<>"",S29,"") -> 25 | I29: =+IF(AA29<>"",AA29,"") -> 110 | J29: =+IF(AB29<>"",AB29,"") | K29: =+IF(AC29<>"",AC29,"") | L29: =+IF(Z29<>"",Z29,"") | M29: =+IF(T29<>"",T29,"") | N29: =+IF(U29<>"",U29,"") | Q29: Electro Oriente S. A. | R29: 10 | S29: 25 | V29: 35 | X29: Electro Oriente S. A. | Y29: 21 | AA29: 110 | AI29: Consorcio Eléctrico Villacurí S.A.C. | AJ29: Hidráulico | AK29: C.H. COELVIHIDRO 1 - QUIPICO | AN29: Chinango S.A.C | AO29: C.H. CHIMAY | AP29: GR-2 | AQ29: Hidráulico | AR29: HI
B30: =+B29+1 -> 23 | C30: =+Q30 -> Electro Puno S.A.A. | D30: =+SUM(F30,H30,M30:N30) -> 3 | E30: =+SUM(G30,I30:L30) -> 4 | F30: =+IF(R30<>"",R30,"") -> 1 | G30: =+IF(Y30<>"",Y30,"") -> 3 | H30: =+IF(S30<>"",S30,"") -> 1 | I30: =+IF(AA30<>"",AA30,"") -> 1 | J30: =+IF(AB30<>"",AB30,"") | K30: =+IF(AC30<>"",AC30,"") | L30: =+IF(Z30<>"",Z30,"") | M30: =+IF(T30<>"",T30,"") -> 1 | N30: =+IF(U30<>"",U30,"") | Q30: Electro Puno S.A.A. | R30: 1 | S30: 1 | T30: 1 | V30: 3 | X30: Electro Puno S.A.A. | Y30: 3 | AA30: 1 | AD30: 1 | AI30: Consorcio Eléctrico Villacurí S.A.C. | AJ30: Térmico | AK30: C.T. SALAS | AN30: Chinango S.A.C | AO30: C.H. YANANGO | AP30: GR-1 | AQ30: Hidráulico | AR30: HI
B31: =+B30+1 -> 24 | C31: =+Q31 -> Electro Sur Este S.A.A. | D31: =+SUM(F31,H31,M31:N31) -> 10 | E31: =+SUM(G31,I31:L31) -> 20 | F31: =+IF(R31<>"",R31,"") -> 7 | G31: =+IF(Y31<>"",Y31,"") -> 17 | H31: =+IF(S31<>"",S31,"") -> 3 | I31: =+IF(AA31<>"",AA31,"") -> 3 | J31: =+IF(AB31<>"",AB31,"") | K31: =+IF(AC31<>"",AC31,"") | L31: =+IF(Z31<>"",Z31,"") | M31: =+IF(T31<>"",T31,"") | N31: =+IF(U31<>"",U31,"") | Q31: Electro Sur Este S.A.A. | R31: 7 | S31: 3 | V31: 10 | X31: Electro Sur Este S.A.A. | Y31: 17 | AA31: 3 | AI31: Consorcio Eléctrico Villacurí S.A.C. | AJ31: Térmico | AK31: C.T. VILLACURI | AN31: Cía Hidroeléctrica San Hilarión S.A.C. | AO31: C.H. SAN HILARION | AP31: G1 | AQ31: Hidráulico | AR31: HI
B32: =+B31+1 -> 25 | C32: =+Q32 -> Electro Ucayali S.A. | D32: =+SUM(F32,H32,M32:N32) -> 4 | E32: =+SUM(G32,I32:L32) -> 11 | F32: =+IF(R32<>"",R32,"") -> 1 | G32: =+IF(Y32<>"",Y32,"") -> 3 | H32: =+IF(S32<>"",S32,"") -> 2 | I32: =+IF(AA32<>"",AA32,"") -> 8 | J32: =+IF(AB32<>"",AB32,"") | K32: =+IF(AC32<>"",AC32,"") | L32: =+IF(Z32<>"",Z32,"") | M32: =+IF(T32<>"",T32,"") -> 1 | N32: =+IF(U32<>"",U32,"") | Q32: Electro Ucayali S.A. | R32: 1 | S32: 2 | T32: 1 | V32: 4 | X32: Electro Ucayali S.A. | Y32: 3 | AA32: 8 | AD32: 1 | AI32: E.A.W. Muller S.A. | AJ32: Hidráulico | AK32: C.H. LA ESPERANZA | AN32: Cogeneración Oquendo S.A.C. | AO32: C.T. OQUENDO | AP32: TG1 | AQ32: Térmico | AR32: TG
B33: =+B32+1 -> 26 | C33: =+Q33 -> Electro Zaña S.A.C. | D33: =+SUM(F33,H33,M33:N33) -> 1 | E33: =+SUM(G33,I33:L33) -> 2 | F33: =+IF(R33<>"",R33,"") -> 1 | G33: =+IF(Y33<>"",Y33,"") -> 2 | H33: =+IF(S33<>"",S33,"") | I33: =+IF(AA33<>"",AA33,"") | J33: =+IF(AB33<>"",AB33,"") | K33: =+IF(AC33<>"",AC33,"") | L33: =+IF(Z33<>"",Z33,"") | M33: =+IF(T33<>"",T33,"") | N33: =+IF(U33<>"",U33,"") | Q33: Electro Zaña S.A.C. | R33: 1 | V33: 1 | X33: Electro Zaña S.A.C. | Y33: 2 | AI33: Eléctrica Yanapampa S.A.C. | AJ33: Hidráulico | AK33: C.H. YANAPAMPA | AN33: Cogeneración Oquendo S.A.C. | AO33: C.T. OQUENDO | AP33: TV1 | AQ33: Térmico | AR33: TV
B34: =+B33+1 -> 27 | C34: =+Q34 -> Electrocentro S.A. | D34: =+SUM(F34,H34,M34:N34) -> 17 | E34: =+SUM(G34,I34:L34) -> 36 | F34: =+IF(R34<>"",R34,"") -> 14 | G34: =+IF(Y34<>"",Y34,"") -> 28 | H34: =+IF(S34<>"",S34,"") -> 3 | I34: =+IF(AA34<>"",AA34,"") -> 8 | J34: =+IF(AB34<>"",AB34,"") | K34: =+IF(AC34<>"",AC34,"") | L34: =+IF(Z34<>"",Z34,"") | M34: =+IF(T34<>"",T34,"") | N34: =+IF(U34<>"",U34,"") | Q34: Electrocentro S.A. | R34: 14 | S34: 3 | V34: 17 | X34: Electrocentro S.A. | Y34: 28 | AA34: 8 | AI34: Electro Dunas S.A.A. | AJ34: Hidráulico | AK34: C.H. LARAMATE | AN34: Cogeneración Oquendo S.A.C. | AO34: C.T. OQUENDO | AP34: TV2 | AQ34: Térmico | AR34: TV
B35: =+B34+1 -> 28 | C35: =+Q35 -> Electronoroeste S. A. | D35: =+SUM(F35,H35,M35:N35) -> 8 | E35: =+SUM(G35,I35:L35) -> 23 | F35: =+IF(R35<>"",R35,"") -> 4 | G35: =+IF(Y35<>"",Y35,"") -> 8 | H35: =+IF(S35<>"",S35,"") -> 4 | I35: =+IF(AA35<>"",AA35,"") -> 14 | J35: =+IF(AB35<>"",AB35,"") -> 1 | K35: =+IF(AC35<>"",AC35,"") | L35: =+IF(Z35<>"",Z35,"") | M35: =+IF(T35<>"",T35,"") | N35: =+IF(U35<>"",U35,"") | Q35: Electronoroeste S. A. | R35: 4 | S35: 4 | V35: 8 | X35: Electronoroeste S. A. | Y35: 8 | AA35: 14 | AB35: 1 | AI35: Electro Dunas S.A.A. | AJ35: Térmico | AK35: C.T. LUREN | AN35: Colca Solar S.A.C. | AO35: C.S. YARUCAYA | AP35: Circuito 1 | AQ35: Solar | AR35: HI
B36: =+B35+1 -> 29 | C36: =+Q36 -> Electronorte S.A. | D36: =+SUM(F36,H36,M36:N36) -> 9 | E36: =+SUM(G36,I36:L36) -> 15 | F36: =+IF(R36<>"",R36,"") -> 4 | G36: =+IF(Y36<>"",Y36,"") -> 9 | H36: =+IF(S36<>"",S36,"") -> 5 | I36: =+IF(AA36<>"",AA36,"") -> 6 | J36: =+IF(AB36<>"",AB36,"") | K36: =+IF(AC36<>"",AC36,"") | L36: =+IF(Z36<>"",Z36,"") | M36: =+IF(T36<>"",T36,"") | N36: =+IF(U36<>"",U36,"") | Q36: Electronorte S.A. | R36: 4 | S36: 5 | V36: 9 | X36: Electronorte S.A. | Y36: 9 | AA36: 6 | AI36: Electro Dunas S.A.A. | AJ36: Térmico | AK36: C.T. EL PEDREGAL | AN36: Compañia Eléctrica El Platanal S.A. | AO36: C.H. EL PLATANAL | AP36: PELTON 1 | AQ36: Hidráulico | AR36: HI
B37: =+B36+1 -> 30 | C37: =+Q37 -> Electroperú S. A. | D37: =+SUM(F37,H37,M37:N37) -> 3 | E37: =+SUM(G37,I37:L37) -> 12 | F37: =+IF(R37<>"",R37,"") -> 2 | G37: =+IF(Y37<>"",Y37,"") -> 10 | H37: =+IF(S37<>"",S37,"") -> 1 | I37: =+IF(AA37<>"",AA37,"") -> 2 | J37: =+IF(AB37<>"",AB37,"") | K37: =+IF(AC37<>"",AC37,"") | L37: =+IF(Z37<>"",Z37,"") | M37: =+IF(T37<>"",T37,"") | N37: =+IF(U37<>"",U37,"") | Q37: Electroperú S. A. | R37: 2 | S37: 1 | V37: 3 | X37: Electroperú S. A. | Y37: 10 | AA37: 2 | AI37: Electro Dunas S.A.A. | AJ37: Térmico | AK37: C.T. NASCA | AN37: Compañia Eléctrica El Platanal S.A. | AO37: C.H. EL PLATANAL | AP37: Pelton 2 | AQ37: Hidráulico | AR37: HI
B38: =+B37+1 -> 31 | C38: =+Q38 -> Emp. de Generación Eléctrica de Arequipa S. A. | D38: =+SUM(F38,H38,M38:N38) -> 8 | E38: =+SUM(G38,I38:L38) -> 20 | F38: =+IF(R38<>"",R38,"") -> 6 | G38: =+IF(Y38<>"",Y38,"") -> 14 | H38: =+IF(S38<>"",S38,"") -> 2 | I38: =+IF(AA38<>"",AA38,"") -> 5 | J38: =+IF(AB38<>"",AB38,"") | K38: =+IF(AC38<>"",AC38,"") | L38: =+IF(Z38<>"",Z38,"") -> 1 | M38: =+IF(T38<>"",T38,"") | N38: =+IF(U38<>"",U38,"") | Q38: Emp. de Generación Eléctrica de Arequipa S. A. | R38: 6 | S38: 2 | V38: 8 | X38: Emp. de Generación Eléctrica de Arequipa S. A. | Y38: 14 | Z38: 1 | AA38: 5 | AI38: Electro Oriente S. A. | AJ38: Hidráulico | AK38: C.H. CACLIC | AN38: Compañia Hidroeléctrica Tingo S.A. | AO38: C.H. TINGO | AP38: Allis Charner 1-4 | AQ38: Hidráulico | AR38: HI
B39: =+B38+1 -> 32 | C39: =+Q39 -> Emp. de Generación Eléctrica del Sur S. A. | D39: =+SUM(F39,H39,M39:N39) -> 3 | E39: =+SUM(G39,I39:L39) -> 7 | F39: =+IF(R39<>"",R39,"") -> 2 | G39: =+IF(Y39<>"",Y39,"") -> 3 | H39: =+IF(S39<>"",S39,"") -> 1 | I39: =+IF(AA39<>"",AA39,"") -> 4 | J39: =+IF(AB39<>"",AB39,"") | K39: =+IF(AC39<>"",AC39,"") | L39: =+IF(Z39<>"",Z39,"") | M39: =+IF(T39<>"",T39,"") | N39: =+IF(U39<>"",U39,"") | Q39: Emp. de Generación Eléctrica del Sur S. A. | R39: 2 | S39: 1 | V39: 3 | X39: Emp. de Generación Eléctrica del Sur S. A. | Y39: 3 | AA39: 4 | AI39: Electro Oriente S. A. | AJ39: Hidráulico | AK39: C.H. EL GERA | AN39: Consorcio Eléctrico Villacurí S.A.C. | AO39: C.H. COELVIHIDRO 1 - QUIPICO | AP39: G-1 | AQ39: Hidráulico | AR39: HI
B40: =+B39+1 -> 33 | C40: =+Q40 -> Emp. Gen y Comercializadora de Serv Pub de Elec. Pangoa | D40: =+SUM(F40,H40,M40:N40) -> 1 | E40: =+SUM(G40,I40:L40) -> 2 | F40: =+IF(R40<>"",R40,"") -> 1 | G40: =+IF(Y40<>"",Y40,"") -> 2 | H40: =+IF(S40<>"",S40,"") | I40: =+IF(AA40<>"",AA40,"") | J40: =+IF(AB40<>"",AB40,"") | K40: =+IF(AC40<>"",AC40,"") | L40: =+IF(Z40<>"",Z40,"") | M40: =+IF(T40<>"",T40,"") | N40: =+IF(U40<>"",U40,"") | Q40: Emp. Gen y Comercializadora de Serv Pub de Elec. Pangoa | R40: 1 | V40: 1 | X40: Emp. Gen y Comercializadora de Serv Pub de Elec. Pangoa | Y40: 2 | AI40: Electro Oriente S. A. | AJ40: Hidráulico | AK40: C.H. EL MUYO | AN40: Consorcio Eléctrico Villacurí S.A.C. | AO40: C.T. SALAS | AP40: G-1 | AQ40: Térmico | AR40: EL
...

Sheet 3.2.1.2
A1: 3.2.1.2. Para uso propio (*) | U1: Informa A | V1: Informante
U2: Tipo de Mercado A | V2: Uso Propio
B3: N° | D3: Número | E3: Hidráulicas | F3: Térmicas | U3: Variable | V3: Energía
C4: Principales empresas | D4: total de | E4: Nº de | F4: Nº de centrales | N4: Cuenta de Central Anuario | O4: Etiquetas de columna | U4: FILTRO | V4: (en blanco)
D5: centrales | E5: centrales | F5: EL | G5: TG | H5: TV | J5: Etiquetas de fila | K5: Cuenta de Central Anuario | N5: Etiquetas de fila | O5: HI | P5: EL | Q5: TG | R5: TV | S5: Total general
B6: 1 | C6: =+J6 -> Agroindustrial Laredo S.A.A. | D6: =+K6 -> 6 | E6: =+IF(O6<>"",O6,"") | F6: =+IF(P6<>"",P6,"") | G6: =+IF(Q6<>"",Q6,"") | H6: =+IF(R6<>"",R6,"") -> 6 | J6: Agroindustrial Laredo S.A.A. | K6: 6 | N6: Agroindustrial Laredo S.A.A. | R6: 6 | S6: 6 | U6: Empresa Anuario | V6: Central Anuario | W6: CTIPGRU
B7: =+B6+1 -> 2 | C7: =+J7 -> Agrolmos S.A. | D7: =+K7 -> 1 | E7: =+IF(O7<>"",O7,"") | F7: =+IF(P7<>"",P7,"") | G7: =+IF(Q7<>"",Q7,"") | H7: =+IF(R7<>"",R7,"") -> 1 | J7: Agrolmos S.A. | K7: 1 | N7: Agrolmos S.A. | R7: 1 | S7: 1 | U7: Agroindustrial Laredo S.A.A. | V7: C.T. TURBO GENERADOR 1 | W7: TV
B8: =+B7+1 -> 3 | C8: =+J8 -> Aguaytia Energy del Peru S.R.L. | D8: =+K8 -> 1 | E8: =+IF(O8<>"",O8,"") | F8: =+IF(P8<>"",P8,"") | G8: =+IF(Q8<>"",Q8,"") -> 1 | H8: =+IF(R8<>"",R8,"") | J8: Aguaytia Energy del Peru S.R.L. | K8: 1 | N8: Aguaytia Energy del Peru S.R.L. | Q8: 1 | S8: 1 | U8: Agroindustrial Laredo S.A.A. | V8: C.T. TURBO GENERADOR 2 | W8: TV
B9: =+B8+1 -> 4 | C9: =+J9 -> Ajeper S.A. | D9: =+K9 -> 1 | E9: =+IF(O9<>"",O9,"") | F9: =+IF(P9<>"",P9,"") -> 1 | G9: =+IF(Q9<>"",Q9,"") | H9: =+IF(R9<>"",R9,"") | J9: Ajeper S.A. | K9: 1 | N9: Ajeper S.A. | P9: 1 | S9: 1 | U9: Agroindustrial Laredo S.A.A. | V9: C.T. TURBO GENERADOR 3 | W9: TV
B10: =+B9+1 -> 5 | C10: =+J10 -> Ajinomoto del Peru S.A. | D10: =+K10 -> 1 | E10: =+IF(O10<>"",O10,"") | F10: =+IF(P10<>"",P10,"") -> 1 | G10: =+IF(Q10<>"",Q10,"") | H10: =+IF(R10<>"",R10,"") | J10: Ajinomoto del Peru S.A. | K10: 1 | N10: Ajinomoto del Peru S.A. | P10: 1 | S10: 1 | U10: Agroindustrial Laredo S.A.A. | V10: C.T. TURBO GENERADOR 4 | W10: TV
B11: =+B10+1 -> 6 | C11: =+J11 -> Alicorp S.A.A. | D11: =+K11 -> 6 | E11: =+IF(O11<>"",O11,"") | F11: =+IF(P11<>"",P11,"") -> 6 | G11: =+IF(Q11<>"",Q11,"") | H11: =+IF(R11<>"",R11,"") | J11: Alicorp S.A.A. | K11: 6 | N11: Alicorp S.A.A. | P11: 6 | S11: 6 | U11: Agroindustrial Laredo S.A.A. | V11: C.T. TURBO GENERADOR 5 | W11: TV
B12: =+B11+1 -> 7 | C12: =+J12 -> Anabi S.A.C. | D12: =+K12 -> 2 | E12: =+IF(O12<>"",O12,"") | F12: =+IF(P12<>"",P12,"") -> 2 | G12: =+IF(Q12<>"",Q12,"") | H12: =+IF(R12<>"",R12,"") | J12: Anabi S.A.C. | K12: 2 | N12: Anabi S.A.C. | P12: 2 | S12: 2 | U12: Agroindustrial Laredo S.A.A. | V12: C.T. UNIDAD DIESEL | W12: TV
B13: =+B12+1 -> 8 | C13: =+J13 -> Anglo American Quellaveco S.A. | D13: =+K13 -> 4 | E13: =+IF(O13<>"",O13,"") | F13: =+IF(P13<>"",P13,"") -> 4 | G13: =+IF(Q13<>"",Q13,"") | H13: =+IF(R13<>"",R13,"") | J13: Anglo American Quellaveco S.A. | K13: 4 | N13: Anglo American Quellaveco S.A. | P13: 4 | S13: 4 | U13: Agrolmos S.A. | V13: C.T. AGROLMOS | W13: TV
B14: =+B13+1 -> 9 | C14: =+J14 -> APM Terminals Callao S.A. | D14: =+K14 -> 1 | E14: =+IF(O14<>"",O14,"") | F14: =+IF(P14<>"",P14,"") -> 1 | G14: =+IF(Q14<>"",Q14,"") | H14: =+IF(R14<>"",R14,"") | J14: APM Terminals Callao S.A. | K14: 1 | N14: APM Terminals Callao S.A. | P14: 1 | S14: 1 | U14: Aguaytia Energy del Peru S.R.L. | V14: C.T. GAS | W14: TG
B15: =+B14+1 -> 10 | C15: =+J15 -> Apumayo S.A.C. | D15: =+K15 -> 1 | E15: =+IF(O15<>"",O15,"") | F15: =+IF(P15<>"",P15,"") -> 1 | G15: =+IF(Q15<>"",Q15,"") | H15: =+IF(R15<>"",R15,"") | J15: Apumayo S.A.C. | K15: 1 | N15: Apumayo S.A.C. | P15: 1 | S15: 1 | U15: Ajeper S.A. | V15: C.T. AJE | W15: EL
B16: =+B15+1 -> 11 | C16: =+J16 -> Aris Indsutrial S.A. | D16: =+K16 -> 2 | E16: =+IF(O16<>"",O16,"") | F16: =+IF(P16<>"",P16,"") -> 2 | G16: =+IF(Q16<>"",Q16,"") | H16: =+IF(R16<>"",R16,"") | J16: Aris Indsutrial S.A. | K16: 2 | N16: Aris Indsutrial S.A. | P16: 2 | S16: 2 | U16: Ajinomoto del Peru S.A. | V16: C.T. AJINOMOTO | W16: EL
B17: =+B16+1 -> 12 | C17: =+J17 -> Aruntani S.A.C. | D17: =+K17 -> 2 | E17: =+IF(O17<>"",O17,"") | F17: =+IF(P17<>"",P17,"") -> 2 | G17: =+IF(Q17<>"",Q17,"") | H17: =+IF(R17<>"",R17,"") | J17: Aruntani S.A.C. | K17: 2 | N17: Aruntani S.A.C. | P17: 2 | S17: 2 | U17: Alicorp S.A.A. | V17: C.T. AREQUIPA | W17: EL
B18: =+B17+1 -> 13 | C18: =+J18 -> Austral Group S.A.A | D18: =+K18 -> 2 | E18: =+IF(O18<>"",O18,"") | F18: =+IF(P18<>"",P18,"") -> 2 | G18: =+IF(Q18<>"",Q18,"") | H18: =+IF(R18<>"",R18,"") | J18: Austral Group S.A.A | K18: 2 | N18: Austral Group S.A.A | P18: 2 | S18: 2 | U18: Alicorp S.A.A. | V18: C.T. FIDEERIA LIMA | W18: EL
B19: =+B18+1 -> 14 | C19: =+J19 -> Cálidda Energía S.A.C. | D19: =+K19 -> 1 | E19: =+IF(O19<>"",O19,"") | F19: =+IF(P19<>"",P19,"") -> 1 | G19: =+IF(Q19<>"",Q19,"") | H19: =+IF(R19<>"",R19,"") | J19: Cálidda Energía S.A.C. | K19: 1 | N19: Cálidda Energía S.A.C. | P19: 1 | S19: 1 | U19: Alicorp S.A.A. | V19: C.T. MOLINOS CALLAO | W19: EL
B20: =+B19+1 -> 15 | C20: =+J20 -> Cartavio S.A.A. | D20: =+K20 -> 1 | E20: =+IF(O20<>"",O20,"") | F20: =+IF(P20<>"",P20,"") | G20: =+IF(Q20<>"",Q20,"") | H20: =+IF(R20<>"",R20,"") -> 1 | J20: Cartavio S.A.A. | K20: 1 | N20: Cartavio S.A.A. | R20: 1 | S20: 1 | U20: Alicorp S.A.A. | V20: C.T. MOLINOS SANTA ROSA | W20: EL
B21: =+B20+1 -> 16 | C21: =+J21 -> Casa Grande S.A.A. | D21: =+K21 -> 1 | E21: =+IF(O21<>"",O21,"") | F21: =+IF(P21<>"",P21,"") | G21: =+IF(Q21<>"",Q21,"") | H21: =+IF(R21<>"",R21,"") -> 1 | J21: Casa Grande S.A.A. | K21: 1 | N21: Casa Grande S.A.A. | R21: 1 | S21: 1 | U21: Alicorp S.A.A. | V21: C.T. NICOVITA TRUJILLO | W21: EL
B22: =+B21+1 -> 17 | C22: =+J22 -> Cementos Pacasmayo S.A.A. | D22: =+K22 -> 1 | E22: =+IF(O22<>"",O22,"") | F22: =+IF(P22<>"",P22,"") | G22: =+IF(Q22<>"",Q22,"") | H22: =+IF(R22<>"",R22,"") -> 1 | J22: Cementos Pacasmayo S.A.A. | K22: 1 | N22: Cementos Pacasmayo S.A.A. | R22: 1 | S22: 1 | U22: Alicorp S.A.A. | V22: C.T. OLEAGINOSA CALLAO | W22: EL
B23: =+B22+1 -> 18 | C23: =+J23 -> Cementos Selva S.A. | D23: =+K23 -> 1 | E23: =+IF(O23<>"",O23,"") | F23: =+IF(P23<>"",P23,"") -> 1 | G23: =+IF(Q23<>"",Q23,"") | H23: =+IF(R23<>"",R23,"") | J23: Cementos Selva S.A. | K23: 1 | N23: Cementos Selva S.A. | P23: 1 | S23: 1 | U23: Anabi S.A.C. | V23: C.T. ANABI | W23: EL
B24: =+B23+1 -> 19 | C24: =+J24 -> Cerámica Lima S.A. | D24: =+K24 -> 2 | E24: =+IF(O24<>"",O24,"") | F24: =+IF(P24<>"",P24,"") -> 2 | G24: =+IF(Q24<>"",Q24,"") | H24: =+IF(R24<>"",R24,"") | J24: Cerámica Lima S.A. | K24: 2 | N24: Cerámica Lima S.A. | P24: 2 | S24: 2 | U24: Anabi S.A.C. | V24: C.T. ANAMA | W24: EL
B25: =+B24+1 -> 20 | C25: =+J25 -> Cervecería San Juan S.A. | D25: =+K25 -> 1 | E25: =+IF(O25<>"",O25,"") | F25: =+IF(P25<>"",P25,"") -> 1 | G25: =+IF(Q25<>"",Q25,"") | H25: =+IF(R25<>"",R25,"") | J25: Cervecería San Juan S.A. | K25: 1 | N25: Cervecería San Juan S.A. | P25: 1 | S25: 1 | U25: Anglo American Quellaveco S.A. | V25: C.T. CORTADERA | W25: EL
B26: =+B25+1 -> 21 | C26: =+J26 -> Cia Minera Agregados Calcáreos S.A. | D26: =+K26 -> 1 | E26: =+IF(O26<>"",O26,"") | F26: =+IF(P26<>"",P26,"") -> 1 | G26: =+IF(Q26<>"",Q26,"") | H26: =+IF(R26<>"",R26,"") | J26: Cia Minera Agregados Calcáreos S.A. | K26: 1 | N26: Cia Minera Agregados Calcáreos S.A. | P26: 1 | S26: 1 | U26: Anglo American Quellaveco S.A. | V26: C.T. SALVIANI | W26: EL
B27: =+B26+1 -> 22 | C27: =+J27 -> Cia Minera Poderosa S.A. | D27: =+K27 -> 3 | E27: =+IF(O27<>"",O27,"") -> 1 | F27: =+IF(P27<>"",P27,"") -> 2 | G27: =+IF(Q27<>"",Q27,"") | H27: =+IF(R27<>"",R27,"") | J27: Cia Minera Poderosa S.A. | K27: 3 | N27: Cia Minera Poderosa S.A. | O27: 1 | P27: 2 | S27: 3 | U27: Anglo American Quellaveco S.A. | V27: C.T. DRENAJE SECTOR MINA | W27: EL
B28: =+B27+1 -> 23 | C28: =+J28 -> Cia Minera Raura S.A. | D28: =+K28 -> 1 | E28: =+IF(O28<>"",O28,"") -> 1 | F28: =+IF(P28<>"",P28,"") | G28: =+IF(Q28<>"",Q28,"") | H28: =+IF(R28<>"",R28,"") | J28: Cia Minera Raura S.A. | K28: 1 | N28: Cia Minera Raura S.A. | O28: 1 | S28: 1 | U28: Anglo American Quellaveco S.A. | V28: C.T. PLANTA PAPUJUNE | W28: EL
B29: =+B28+1 -> 24 | C29: =+J29 -> Cia Minera Santa Luisa S.A. | D29: =+K29 -> 5 | E29: =+IF(O29<>"",O29,"") -> 2 | F29: =+IF(P29<>"",P29,"") -> 3 | G29: =+IF(Q29<>"",Q29,"") | H29: =+IF(R29<>"",R29,"") | J29: Cia Minera Santa Luisa S.A. | K29: 5 | N29: Cia Minera Santa Luisa S.A. | O29: 2 | P29: 3 | S29: 5 | U29: APM Terminals Callao S.A. | V29: C.T. PUERTO CALLAO | W29: EL
B30: =+B29+1 -> 25 | C30: =+J30 -> CNPC Perú S.A. | D30: =+K30 -> 1 | E30: =+IF(O30<>"",O30,"") | F30: =+IF(P30<>"",P30,"") -> 1 | G30: =+IF(Q30<>"",Q30,"") | H30: =+IF(R30<>"",R30,"") | J30: CNPC Perú S.A. | K30: 1 | N30: CNPC Perú S.A. | P30: 1 | S30: 1 | U30: Apumayo S.A.C. | V30: C.T. APUMAYO | W30: EL
B31: =+B30+1 -> 26 | C31: =+J31 -> Compañía Minera Antapaccay S.A. | D31: =+K31 -> 1 | E31: =+IF(O31<>"",O31,"") | F31: =+IF(P31<>"",P31,"") -> 1 | G31: =+IF(Q31<>"",Q31,"") | H31: =+IF(R31<>"",R31,"") | J31: Compañía Minera Antapaccay S.A. | K31: 1 | N31: Compañía Minera Antapaccay S.A. | P31: 1 | S31: 1 | U31: Aris Indsutrial S.A. | V31: C.T. ARIS LIMA | W31: EL
B32: =+B31+1 -> 27 | C32: =+J32 -> Compañía Minera Ares S.A.C. | D32: =+K32 -> 6 | E32: =+IF(O32<>"",O32,"") | F32: =+IF(P32<>"",P32,"") -> 6 | G32: =+IF(Q32<>"",Q32,"") | H32: =+IF(R32<>"",R32,"") | J32: Compañía Minera Ares S.A.C. | K32: 6 | N32: Compañía Minera Ares S.A.C. | P32: 6 | S32: 6 | U32: Aris Indsutrial S.A. | V32: C.T. ARIS LURIN | W32: EL
B33: =+B32+1 -> 28 | C33: =+J33 -> Compañía Minera Caraveli S.A.C. | D33: =+K33 -> 2 | E33: =+IF(O33<>"",O33,"") | F33: =+IF(P33<>"",P33,"") -> 2 | G33: =+IF(Q33<>"",Q33,"") | H33: =+IF(R33<>"",R33,"") | J33: Compañía Minera Caraveli S.A.C. | K33: 2 | N33: Compañía Minera Caraveli S.A.C. | P33: 2 | S33: 2 | U33: Aruntani S.A.C. | V33: C.T. JESICA | W33: EL
B34: =+B33+1 -> 29 | C34: =+J34 -> Compañía Minera Chungar S.A.C. | D34: =+K34 -> 14 | E34: =+IF(O34<>"",O34,"") -> 11 | F34: =+IF(P34<>"",P34,"") -> 3 | G34: =+IF(Q34<>"",Q34,"") | H34: =+IF(R34<>"",R34,"") | J34: Compañía Minera Chungar S.A.C. | K34: 14 | N34: Compañía Minera Chungar S.A.C. | O34: 11 | P34: 3 | S34: 14 | U34: Aruntani S.A.C. | V34: C.T. TUCARI | W34: EL
B35: =+B34+1 -> 30 | C35: =+J35 -> Compañia Minera Kolpa S.A. | D35: =+K35 -> 1 | E35: =+IF(O35<>"",O35,"") | F35: =+IF(P35<>"",P35,"") -> 1 | G35: =+IF(Q35<>"",Q35,"") | H35: =+IF(R35<>"",R35,"") | J35: Compañia Minera Kolpa S.A. | K35: 1 | N35: Compañia Minera Kolpa S.A. | P35: 1 | S35: 1 | U35: Austral Group S.A.A | V35: C.T. PLANTA CHANCAY | W35: EL
B36: =+B35+1 -> 31 | C36: =+J36 -> Compañía Minera San Ignacio de Morococha S.A.A. | D36: =+K36 -> 2 | E36: =+IF(O36<>"",O36,"") -> 1 | F36: =+IF(P36<>"",P36,"") -> 1 | G36: =+IF(Q36<>"",Q36,"") | H36: =+IF(R36<>"",R36,"") | J36: Compañía Minera San Ignacio de Morococha S.A.A. | K36: 2 | N36: Compañía Minera San Ignacio de Morococha S.A.A. | O36: 1 | P36: 1 | S36: 2 | U36: Austral Group S.A.A | V36: C.T. PLANTA PISCO | W36: EL
B37: =+B36+1 -> 32 | C37: =+J37 -> Compañía Minera San Valentin S.A. | D37: =+K37 -> 1 | E37: =+IF(O37<>"",O37,"") -> 1 | F37: =+IF(P37<>"",P37,"") | G37: =+IF(Q37<>"",Q37,"") | H37: =+IF(R37<>"",R37,"") | J37: Compañía Minera San Valentin S.A. | K37: 1 | N37: Compañía Minera San Valentin S.A. | O37: 1 | S37: 1 | U37: Cálidda Energía S.A.C. | V37: C.T. PURUCHUCO | W37: EL
B38: =+B37+1 -> 33 | C38: =+J38 -> Compañía Pesquera del Pacifico Centro S.A. | D38: =+K38 -> 1 | E38: =+IF(O38<>"",O38,"") | F38: =+IF(P38<>"",P38,"") -> 1 | G38: =+IF(Q38<>"",Q38,"") | H38: =+IF(R38<>"",R38,"") | J38: Compañía Pesquera del Pacifico Centro S.A. | K38: 1 | N38: Compañía Pesquera del Pacifico Centro S.A. | P38: 1 | S38: 1 | U38: Cartavio S.A.A. | V38: C.T. CARTAVIO | W38: TV
B39: =+B38+1 -> 34 | C39: =+J39 -> Compañia Quimica S.A. | D39: =+K39 -> 1 | E39: =+IF(O39<>"",O39,"") | F39: =+IF(P39<>"",P39,"") -> 1 | G39: =+IF(Q39<>"",Q39,"") | H39: =+IF(R39<>"",R39,"") | J39: Compañia Quimica S.A. | K39: 1 | N39: Compañia Quimica S.A. | P39: 1 | S39: 1 | U39: Casa Grande S.A.A. | V39: C.T. CASA GRANDE | W39: TV
B40: =+B39+1 -> 35 | C40: =+J40 -> Consorcio Minero Horizonte S.A. | D40: =+K40 -> 2 | E40: =+IF(O40<>"",O40,"") -> 1 | F40: =+IF(P40<>"",P40,"") -> 1 | G40: =+IF(Q40<>"",Q40,"") | H40: =+IF(R40<>"",R40,"") | J40: Consorcio Minero Horizonte S.A. | K40: 2 | N40: Consorcio Minero Horizonte S.A. | O40: 1 | P40: 1 | S40: 2 | U40: Cementos Pacasmayo S.A.A. | V40: C.T. PACASMAYO | W40: TV
...

Sheet 3.2.2.1
B1: 3.2.2 Centrales eléctricas representativas por tipo de generación | J1: P.I. TOTAL | K1: 16530.989 | L1: PRODUCC. TOT | M1: 63794.884
K2: Tipo de Mercado A | L2: Mercado Eléctrico
B3: 3.2.2.1 Centrales Hidráulicas | K3: Informa A | L3: Informante
K4: Origen A | L4: Hidráulico
B5: Empresa | C5: Central | D5: Potencia Instalada | F5: Producción | K5: FILTRO | L5: (en blanco)
D6: (MW) | E6: % P.I. | F6: GWh | G6: % P.B.
K7: Empresa Anuario | L7: Central Anuario | M7: Suma de PI OK | N7: Suma de Energia (GWh)
B8: Electroperú S. A. | C8: C.H. ANTUNEZ DE MAYOLO | D8: 798 | E8: 4.8272974 | F8: 5261.7876 | G8: 8.2479774 | K8: Electroperú S. A. | L8: C.H. ANTUNEZ DE MAYOLO | M8: 798 | N8: 5261.7876
B9: Electroperú S. A. | C9: C.H. RESTITUCION | D9: 210.36 | E9: 1.2725191 | F9: 1681.6239 | G9: 2.6359856 | K9: Electroperú S. A. | L9: C.H. RESTITUCION | M9: 210.36 | N9: 1681.6239
K10: Total Electroperú S. A. | M10: 1008.36 | N10: 6943.4116
B11: Kallpa Generación S.A. | C11: C.H. CERRO DEL AGUILA | D11: 524.6 | E11: 3.1734338 | F11: 3480.832 | G11: 5.4562871 | K11: Kallpa Generación S.A. | L11: C.H. CERRO DEL AGUILA | M11: 524.6 | N11: 3480.832
K12: Total Kallpa Generación S.A. | M12: 524.6 | N12: 3480.832
B13: Empresa de Generación Huallaga S.A. | C13: C.H. CHAGLLA | D13: 467.785 | E13: 2.829746 | F13: 2064.6622 | G13: 3.2364072 | K13: Empresa de Generación Huallaga S.A. | L13: C.H. CHAGLLA | M13: 467.785 | N13: 2064.6622
K14: Total Empresa de Generación Huallaga S.A. | M14: 467.785 | N14: 2064.6622
B15: Emp. de Generación Eléctrica de Arequipa S. A. | C15: C.H. CHARCANI V | D15: 146.86 | E15: 0.8883921 | F15: 697.39646 | G15: 1.0931856 | K15: Emp. de Generación Eléctrica de Arequipa S. A. | L15: C.H. CHARCANI V | M15: 146.86 | N15: 697.39646 | P15: Tipo de Mercado A | Q15: Mercado Eléctrico
K16: Total Emp. de Generación Eléctrica de Arequipa S. A. | M16: 146.86 | N16: 697.39646 | P16: Informa A | Q16: Informante
B17: Emp. de Generación Eléctrica Machu Picchu S. A. | C17: C.H. MACHUPICCHU | D17: 192.45 | E17: 1.1641772 | F17: 1252.2207 | G17: 1.9628857 | K17: Empresa de Generacion Electrica Machupicchu S.A. | L17: C.H. MACHUPICCHU | M17: 192.45 | N17: 1252.2207 | P17: Origen A | Q17: Hidráulico
K18: Total Empresa de Generacion Electrica Machupicchu S.A. | M18: 192.45 | N18: 1252.2207 | P18: FILTRO | Q18: (en blanco)
B19: Empresa de Generación Eléctrica San Gabán S. A. | C19: C.H. SAN GABAN II | D19: 114 | E19: 0.68961391 | F19: 764.19523 | G19: 1.1978942 | K19: Empresa de Generación Eléctrica San Gabán S. A. | L19: C.H. SAN GABAN II | M19: 114 | N19: 764.19523
K20: Total Empresa de Generación Eléctrica San Gabán S. A. | M20: 114 | N20: 764.19523 | P20: Empresa Anuario | Q20: Central Anuario | R20: Suma de PI OK | S20: Suma de Energia (GWh)
B21: Enel Generación Perú S.A.A. | C21: C.H. HUINCO | D21: 258.4 | E21: 1.5631249 | F21: 1297.6523 | G21: 2.0341008 | K21: Orygen Perú S.A.A. | L21: C.H. HUINCO | M21: 258.4 | N21: 481.80661 | P21: Enel Generación Perú S.A.A. | Q21: C.H. HUINCO | R21: 0 | S21: 815.84566
B22: Enel Generación Perú S.A.A. | C22: C.H. MATUCANA | D22: 120 | E22: 0.72590938 | F22: 922.15217 | G22: 1.4454955 | K22: Orygen Perú S.A.A. | L22: C.H. MATUCANA | M22: 120 | N22: 353.97133 | P22: Enel Generación Perú S.A.A. | Q22: C.H. MATUCANA | R22: 0 | S22: 568.18084
K23: Total Orygen Perú S.A.A. | M23: 378.4 | N23: 835.77794 | P23: Total Enel Generación Perú S.A.A. | R23: 0 | S23: 1384.0265
B24: ENGIE EnergÍa Perú S.A. | C24: C.H. YUNCÁN | D24: 136.759 | E24: 0.82728868 | F24: 789.10095 | G24: 1.2369345 | K24: ENGIE EnergÍa Perú S.A. | L24: C.H. YUNCÁN | M24: 136.759 | N24: 789.10095 | P24: Total general | R24: 0 | S24: 1384.0265
B25: ENGIE EnergÍa Perú S.A. | C25: C.H. QUITARACSA | D25: 111 | E25: 0.67146618 | F25: 457.3347 | G25: 0.71688303 | K25: ENGIE EnergÍa Perú S.A. | L25: C.H. QUITARACSA | M25: 111 | N25: 457.3347
K26: Total ENGIE EnergÍa Perú S.A. | M26: 247.759 | N26: 1246.4357
B27: Luz del Sur S.A. | C27: C.H. SANTA TERESA | D27: 100 | E27: 0.60492448 | F27: 617.27995 | G27: 0.96760101 | K27: Inland Energy S.A.C. | L27: C.H. SANTA TERESA | M27: 100 | N27: 617.27995
K28: Total Inland Energy S.A.C. | M28: 100 | N28: 617.27995
B29: Orazul Energy Perú S.A. | C29: C.H. CAÑON DEL PATO | D29: 246.582 | E29: 1.4916349 | F29: 1528.3387 | G29: 2.3957073 | K29: Orazul Energy Perú S.A. | L29: C.H. CAÑON DEL PATO | M29: 246.582 | N29: 1528.3387
K30: Total Orazul Energy Perú S.A. | M30: 246.582 | N30: 1528.3387
B31: Chinango S.A.C | C31: C.H. CHIMAY | D31: 153 | E31: 0.92553446 | F31: 770.18096 | G31: 1.207277 | K31: Chinango S.A.C | L31: C.H. CHIMAY | M31: 153 | N31: 770.18096
K32: Total Chinango S.A.C | M32: 153 | N32: 770.18096
B33: Compañia Eléctrica El Platanal S.A. | C33: C.H. EL PLATANAL | D33: 220 | E33: 1.3308339 | F33: 1188.4125 | G33: 1.8628648 | K33: Compañia Eléctrica El Platanal S.A. | L33: C.H. EL PLATANAL | M33: 220 | N33: 1188.4125
K34: Total Compañia Eléctrica El Platanal S.A. | M34: 220 | N34: 1188.4125
B35: Statkraft Perú S.A. | C35: C.H. CHEVES | D35: 171.68 | E35: 1.0385344 | F35: 885.0034 | G35: 1.3872639 | K35: Statkraft Perú S.A. | L35: C.H. CHEVES | M35: 171.68 | N35: 885.0034
B36: Statkraft Perú S.A. | C36: C.H. YAUPI | D36: 113.686 | E36: 0.68771445 | F36: 784.51438 | G36: 1.229745 | K36: Statkraft Perú S.A. | L36: C.H. YAUPI | M36: 113.686 | N36: 784.51438
K37: Total general | M37: 4085.162 | N37: 23058.662
B39: % P.I. : Es el porcentaje respecto a la potencia instalada total 2024
B40: % P.B. : Es el porcentaje respecto a la producción de energía total 2024 | K40: Tipo de Mercado A | L40: Mercado Eléctrico
K41: Informa A | L41: Informante
...

Sheet 3.2.2.3
A1: 3.2.2.3. Centrales del mercado electrico con Recursos Energéticos Renovables (RER*) | K1: Tipo de Mercado A | L1: Mercado Eléctrico
K2: Informa A | L2: Informante
B3: Empresa | C3: Central | D3: N° de Subasta RER | E3: Integrante | F3: Recurso | G3: PI | H3: PE | I3: Producción | K3: RER | L3: RER
G4: (MW) | H4: (MW) | I4: GWh
B5: Hidráulicas | K5: Origen A | L5: Empresa Anuario | M5: Central Anuario | N5: N° de Subasta RER | O5: Tipo de Integrante A | P5: Tipo de Recurso | Q5: Suma de PI OK | R5: Suma de PE OK | S5: Suma de Energia (GWh)
B6: =IF(L6<>"",L6,"") -> Andean Power S.A.C. | C6: =IF(M6<>"",M6,"") -> C.H. CARHUAC | D6: =IF(N6<>"",N6,"") -> TERCERA | E6: =IF(O6<>"",O6,"") -> COES | G6: =+Q6 -> 20 | H6: =+R6 -> 20 | I6: =+S6 -> 126.51936 | K6: Hidráulico | L6: Andean Power S.A.C. | M6: C.H. CARHUAC | N6: TERCERA | O6: COES | P6: Agua | Q6: 20 | R6: 20 | S6: 126.51936
B7: =IF(L7<>"",L7,"") -> Atria Energía S.A.C. | C7: =IF(M7<>"",M7,"") -> C.H. PURMACANA | D7: =IF(N7<>"",N7,"") -> PRIMERA | E7: =IF(O7<>"",O7,"") -> COES | G7: =+Q7 -> 1.8 | H7: =+R7 -> 1.79 | I7: =+S7 -> 2.082686 | L7: Atria Energía S.A.C. | M7: C.H. PURMACANA | N7: PRIMERA | O7: COES | P7: Agua | Q7: 1.8 | R7: 1.79 | S7: 2.082686
B8: =IF(L8<>"",L8,"") -> Eléctrica Yanapampa S.A.C. | C8: =IF(M8<>"",M8,"") -> C.H. YANAPAMPA | D8: =IF(N8<>"",N8,"") -> PRIMERA | E8: =IF(O8<>"",O8,"") -> COES | G8: =+Q8 -> 4.155 | H8: =+R8 -> 3.91 | I8: =+S8 -> 24.716961 | L8: Eléctrica Yanapampa S.A.C. | M8: C.H. YANAPAMPA | N8: PRIMERA | O8: COES | P8: Agua | Q8: 4.155 | R8: 3.91 | S8: 24.716961
B9: =IF(L9<>"",L9,"") -> Electro Oriente S. A. | C9: =IF(M9<>"",M9,"") -> C.H. QUANDA | D9: =IF(N9<>"",N9,"") -> - | E9: =IF(O9<>"",O9,"") -> NO COES | G9: =+Q9 -> 2.876 | H9: =+R9 -> 2.8 | I9: =+S9 -> 8.377812 | L9: Electro Oriente S. A. | M9: C.H. QUANDA | N9: - | O9: NO COES | P9: Agua | Q9: 2.876 | R9: 2.8 | S9: 8.377812
B10: =IF(L10<>"",L10,"") -> Electro Zaña S.A.C. | C10: =IF(M10<>"",M10,"") -> C.H. ZAÑA | D10: =IF(N10<>"",N10,"") -> TERCERA | E10: =IF(O10<>"",O10,"") -> NO COES | G10: =+Q10 -> 13.2 | H10: =+R10 -> 13.167 | I10: =+S10 -> 78.10708 | L10: Electro Zaña S.A.C. | M10: C.H. ZAÑA | N10: TERCERA | O10: NO COES | P10: Agua | Q10: 13.2 | R10: 13.167 | S10: 78.10708
B11: =IF(L11<>"",L11,"") -> Empresa de Generación Eléctrica Canchayllo S.A.C. | C11: =IF(M11<>"",M11,"") -> C.H. CANCHAYLLO | D11: =IF(N11<>"",N11,"") -> SEGUNDA | E11: =IF(O11<>"",O11,"") -> COES | G11: =+Q11 -> 5 | H11: =+R11 -> 5 | I11: =+S11 -> 31.368687 | L11: Empresa de Generación Eléctrica Canchayllo S.A.C. | M11: C.H. CANCHAYLLO | N11: SEGUNDA | O11: COES | P11: Agua | Q11: 5 | R11: 5 | S11: 31.368687
B12: =IF(L12<>"",L12,"") -> Empresa de Generación Eléctrica Junín S.A.C. | C12: =IF(M12<>"",M12,"") -> C.H. HUASAHUASI I | D12: =IF(N12<>"",N12,"") -> PRIMERA | E12: =IF(O12<>"",O12,"") -> COES | G12: =+Q12 -> 9.85 | H12: =+R12 -> 9.85 | I12: =+S12 -> 45.039692 | L12: Empresa de Generación Eléctrica Junín S.A.C. | M12: C.H. HUASAHUASI I | N12: PRIMERA | O12: COES | P12: Agua | Q12: 9.85 | R12: 9.85 | S12: 45.039692
B13: =IF(L13<>"",L13,"") | C13: =IF(M13<>"",M13,"") -> C.H. HUASAHUASI II | D13: =IF(N13<>"",N13,"") -> PRIMERA | E13: =IF(O13<>"",O13,"") -> COES | G13: =+Q13 -> 9.964 | H13: =+R13 -> 9.964 | I13: =+S13 -> 48.092614 | M13: C.H. HUASAHUASI II | N13: PRIMERA | O13: COES | P13: Agua | Q13: 9.964 | R13: 9.964 | S13: 48.092614
B14: =IF(L14<>"",L14,"") | C14: =IF(M14<>"",M14,"") -> C.H. RUNATULLO II | D14: =IF(N14<>"",N14,"") -> TERCERA | E14: =IF(O14<>"",O14,"") -> COES | G14: =+Q14 -> 19.968 | H14: =+R14 -> 19.968 | I14: =+S14 -> 96.77889 | M14: C.H. RUNATULLO II | N14: TERCERA | O14: COES | P14: Agua | Q14: 19.968 | R14: 19.968 | S14: 96.77889
B15: =IF(L15<>"",L15,"") | C15: =IF(M15<>"",M15,"") -> C.H. RUNATULLO III | D15: =IF(N15<>"",N15,"") -> SEGUNDA | E15: =IF(O15<>"",O15,"") -> COES | G15: =+Q15 -> 19.966 | H15: =+R15 -> 19.966 | I15: =+S15 -> 109.73273 | M15: C.H. RUNATULLO III | N15: SEGUNDA | O15: COES | P15: Agua | Q15: 19.966 | R15: 19.966 | S15: 109.73273
B16: =IF(L16<>"",L16,"") | C16: =IF(M16<>"",M16,"") -> C.H. SANTA CRUZ I | D16: =IF(N16<>"",N16,"") -> PRIMERA | E16: =IF(O16<>"",O16,"") -> COES | G16: =+Q16 -> 6.636 | H16: =+R16 -> 6.636 | I16: =+S16 -> 37.481772 | M16: C.H. SANTA CRUZ I | N16: PRIMERA | O16: COES | P16: Agua | Q16: 6.636 | R16: 6.636 | S16: 37.481772
B17: =IF(L17<>"",L17,"") | C17: =IF(M17<>"",M17,"") -> C.H. SANTA CRUZ II | D17: =IF(N17<>"",N17,"") -> PRIMERA | E17: =IF(O17<>"",O17,"") -> COES | G17: =+Q17 -> 6.502 | H17: =+R17 -> 6.502 | I17: =+S17 -> 39.230236 | M17: C.H. SANTA CRUZ II | N17: PRIMERA | O17: COES | P17: Agua | Q17: 6.502 | R17: 6.502 | S17: 39.230236
B18: =IF(L18<>"",L18,"") -> Empresa de Generación Eléctrica Rio Baños S.A.C. | C18: =IF(M18<>"",M18,"") -> C.H. RUCUY | D18: =IF(N18<>"",N18,"") -> CUARTA | E18: =IF(O18<>"",O18,"") -> COES | G18: =+Q18 -> 20 | H18: =+R18 -> 20 | I18: =+S18 -> 132.80746 | L18: Empresa de Generación Eléctrica Rio Baños S.A.C. | M18: C.H. RUCUY | N18: CUARTA | O18: COES | P18: Agua | Q18: 20 | R18: 20 | S18: 132.80746
B19: =IF(L19<>"",L19,"") -> Empresa de Generación Eléctrica Santa Ana S.R.L. | C19: =IF(M19<>"",M19,"") -> C.H. RENOVANDES | D19: =IF(N19<>"",N19,"") -> SEGUNDA | E19: =IF(O19<>"",O19,"") -> COES | G19: =+Q19 -> 20.862 | H19: =+R19 -> 20.862 | I19: =+S19 -> 163.10162 | L19: Empresa de Generación Eléctrica Santa Ana S.R.L. | M19: C.H. RENOVANDES | N19: SEGUNDA | O19: COES | P19: Agua | Q19: 20.862 | R19: 20.862 | S19: 163.10162
B20: =IF(L20<>"",L20,"") -> Empresa Eléctrica Agua Azul S.A. | C20: =IF(M20<>"",M20,"") -> C.H. POTRERO | D20: =IF(N20<>"",N20,"") -> TERCERA | E20: =IF(O20<>"",O20,"") -> COES | G20: =+Q20 -> 19.9 | H20: =+R20 -> 19.9 | I20: =+S20 -> 97.253144 | L20: Empresa Eléctrica Agua Azul S.A. | M20: C.H. POTRERO | N20: TERCERA | O20: COES | P20: Agua | Q20: 19.9 | R20: 19.9 | S20: 97.253144
B21: =IF(L21<>"",L21,"") -> Empresa Eléctrica Rio Doble S.A. | C21: =IF(M21<>"",M21,"") -> C.H. LAS PIZARRAS | D21: =IF(N21<>"",N21,"") -> PRIMERA | E21: =IF(O21<>"",O21,"") -> COES | G21: =+Q21 -> 20 | H21: =+R21 -> 19.19 | I21: =+S21 -> 85.293915 | L21: Empresa Eléctrica Rio Doble S.A. | M21: C.H. LAS PIZARRAS | N21: PRIMERA | O21: COES | P21: Agua | Q21: 20 | R21: 19.19 | S21: 85.293915
B22: =IF(L22<>"",L22,"") -> Generación Andina S.A.C. | C22: =IF(M22<>"",M22,"") -> C.H. 8 DE AGOSTO | D22: =IF(N22<>"",N22,"") -> SEGUNDA | E22: =IF(O22<>"",O22,"") -> COES | G22: =+Q22+Q39 -> 21.28 | H22: =+R22+R39 -> 21.28 | I22: =+S22+S39 -> 110.6015 | L22: Generación Andina S.A.C. | M22: C.H. 8 DE AGOSTO | N22: SEGUNDA | O22: COES | P22: Agua | Q22: 21.28 | R22: 21.28 | S22: 108.20387
B23: =IF(L23<>"",L23,"") | C23: =IF(M23<>"",M23,"") -> C.H. EL CARMEN | D23: =IF(N23<>"",N23,"") -> SEGUNDA | E23: =IF(O23<>"",O23,"") -> COES | G23: =+Q23 -> 8.4 | H23: =+R23 -> 8.4 | I23: =+S23 -> 43.202421 | M23: C.H. EL CARMEN | N23: SEGUNDA | O23: COES | P23: Agua | Q23: 8.4 | R23: 8.4 | S23: 43.202421
B24: =IF(L24<>"",L24,"") -> Generadora de Energía del Perú S.A. | C24: =IF(M24<>"",M24,"") -> C.H. LA JOYA | D24: =IF(N24<>"",N24,"") -> PRIMERA | E24: =IF(O24<>"",O24,"") -> COES | G24: =+Q24 -> 10.4 | H24: =+R24 -> 10.2 | I24: =+S24 -> 48.995694 | L24: Generadora de Energía del Perú S.A. | M24: C.H. LA JOYA | N24: PRIMERA | O24: COES | P24: Agua | Q24: 10.4 | R24: 10.2 | S24: 48.995694
B25: =IF(L25<>"",L25,"") | C25: =IF(M25<>"",M25,"") -> C.H. ANGEL I | D25: =IF(N25<>"",N25,"") -> PRIMERA | E25: =IF(O25<>"",O25,"") -> COES | G25: =+Q25 -> 20 | H25: =+R25 -> 20.05 | I25: =+S25 -> 99.472449 | M25: C.H. ANGEL I | N25: PRIMERA | O25: COES | P25: Agua | Q25: 20 | R25: 20.05 | S25: 99.472449
B26: =IF(L26<>"",L26,"") | C26: =IF(M26<>"",M26,"") -> C.H. ANGEL II | D26: =IF(N26<>"",N26,"") -> PRIMERA | E26: =IF(O26<>"",O26,"") -> COES | G26: =+Q26 -> 20 | H26: =+R26 -> 19.99 | I26: =+S26 -> 105.62399 | M26: C.H. ANGEL II | N26: PRIMERA | O26: COES | P26: Agua | Q26: 20 | R26: 19.99 | S26: 105.62399
B27: =IF(L27<>"",L27,"") | C27: =IF(M27<>"",M27,"") -> C.H. ANGEL III | D27: =IF(N27<>"",N27,"") -> PRIMERA | E27: =IF(O27<>"",O27,"") -> COES | G27: =+Q27 -> 20 | H27: =+R27 -> 20.08 | I27: =+S27 -> 104.57288 | M27: C.H. ANGEL III | N27: PRIMERA | O27: COES | P27: Agua | Q27: 20 | R27: 20.08 | S27: 104.57288
B28: =IF(L28<>"",L28,"") -> Hidrocañete S.A. | C28: =IF(M28<>"",M28,"") -> C.H. NUEVO IMPERIAL | D28: =IF(N28<>"",N28,"") -> PRIMERA | E28: =IF(O28<>"",O28,"") -> COES | G28: =+Q28 -> 3.97 | H28: =+R28 -> 3.97 | I28: =+S28 -> 27.9163 | L28: Hidrocañete S.A. | M28: C.H. NUEVO IMPERIAL | N28: PRIMERA | O28: COES | P28: Agua | Q28: 3.97 | R28: 3.97 | S28: 27.9163
B29: =IF(L29<>"",L29,"") -> Hidroeléctrica Huanchor S.A.C. | C29: =IF(M29<>"",M29,"") -> C.H. HUANCHOR | D29: =IF(N29<>"",N29,"") -> - | E29: =IF(O29<>"",O29,"") -> COES | G29: =+Q29 -> 20 | H29: =+R29 -> 19.768 | I29: =+S29 -> 157.45968 | L29: Hidroeléctrica Huanchor S.A.C. | M29: C.H. HUANCHOR | N29: - | O29: COES | P29: Agua | Q29: 20 | R29: 19.768 | S29: 157.45968
B30: =IF(L30<>"",L30,"") -> Huaura Power Group S.A. | C30: =IF(M30<>"",M30,"") -> C.H. YARUCAYA | D30: =IF(N30<>"",N30,"") -> TERCERA | E30: =IF(O30<>"",O30,"") -> COES | G30: =+Q30 -> 19.2 | H30: =+R30 -> 18.43 | I30: =+S30 -> 137.5036 | L30: Huaura Power Group S.A. | M30: C.H. YARUCAYA | N30: TERCERA | O30: COES | P30: Agua | Q30: 19.2 | R30: 18.43 | S30: 137.5036
B31: =IF(L31<>"",L31,"") -> Maja Energía S.A.C. | C31: =IF(M31<>"",M31,"") -> C.H. RONCADOR | D31: =IF(N31<>"",N31,"") -> PRIMERA | E31: =IF(O31<>"",O31,"") -> COES | G31: =+Q31 -> 3.8 | H31: =+R31 -> 3.684 | I31: =+S31 -> 23.799409 | L31: Maja Energía S.A.C. | M31: C.H. RONCADOR | N31: PRIMERA | O31: COES | P31: Agua | Q31: 3.8 | R31: 3.684 | S31: 23.799409
B32: =IF(L32<>"",L32,"") -> Orazul Energy Perú S.A. | C32: =IF(M32<>"",M32,"") -> C.H. CAÑA BRAVA | D32: =IF(N32<>"",N32,"") -> PRIMERA | E32: =IF(O32<>"",O32,"") -> COES | G32: =+Q32 -> 6 | H32: =+R32 -> 5.67 | I32: =+S32 -> 27.989162 | L32: Orazul Energy Perú S.A. | M32: C.H. CAÑA BRAVA | N32: PRIMERA | O32: COES | P32: Agua | Q32: 6 | R32: 5.67 | S32: 27.989162
B33: =IF(L33<>"",L33,"") | C33: =IF(M33<>"",M33,"") -> C.H. CARHUAQUERO IV | D33: =IF(N33<>"",N33,"") -> PRIMERA | E33: =IF(O33<>"",O33,"") -> COES | G33: =+Q33 -> 10 | H33: =+R33 -> 9.983 | I33: =+S33 -> 71.382055 | M33: C.H. CARHUAQUERO IV | N33: PRIMERA | O33: COES | P33: Agua | Q33: 10 | R33: 9.983 | S33: 71.382055
B34: =IF(L34<>"",L34,"") -> Orygen Perú S.A.A. | C34: =IF(M34<>"",M34,"") -> C.H. HER 1 | D34: =IF(N34<>"",N34,"") -> CUARTA | E34: =IF(O34<>"",O34,"") -> COES | G34: =+Q34 -> 0.7 | H34: =+R34 -> 0.678 | I34: =+S34 -> 2.267619 | L34: Orygen Perú S.A.A. | M34: C.H. HER 1 | N34: CUARTA | O34: COES | P34: Agua | Q34: 0.7 | R34: 0.678 | S34: 2.267619
